Workbook

Sheet Dashboard
F1: MONTH
B17: Today | C17: Month | D17: Last Week | E17: Yesterday | H17: Vendors | I17: Bought | J17: Sold | K17: Stock | L17: Revenue | M17: Spent | N17: Profit | O17: % | Q17: Last 20 Sold | R17: Profit | S17: Vendor | T17: Date
A18: RVN | B18: =SUMIFS(Inventory!F2:F7005, Inventory!J2:J7005, "closed", Inventory!D2:D7005, "="&TODAY()) -> 0 | C18: =SUMIFS(Inventory!F2:F7005, Inventory!J2:J7005, "closed", Inventory!D2:D7005, ">="&DATE(YEAR(TODAY()), MONTH(TODAY()), 1), Inventory!D2:D7005, "<="&EOMONTH(TODAY(), 0)) -> 30.89 | D18: =SUMIFS(Inventory!F2:F7005, Inventory!J2:J7005, "closed", Inventory!D2:D7005, ">="&TODAY()-WEEKDAY(TODAY(), 2)-7, Inventory!D2:D7005, "<="&TODAY()-WEEKDAY(TODAY(), 2)-1) -> 138.07 | E18: =SUMIFS(Inventory!F2:F7005, Inventory!J2:J7005, "closed", Inventory!D2:D7005, "="&TODAY()-1) -> 0 | H18: Other | I18: =COUNTIF(Inventory!B:B,H18) -> 66 | J18: =COUNTIFS(Inventory!B:B,H18,Inventory!J:J,"Closed") -> 65 | K18: =(I18-J18) -> 1 | L18: =SUMIF(Inventory!B:B,H18,Inventory!F:F) -> 1371.59 | M18: =SUMIF(Inventory!B:B,H18,Inventory!E:E) -> 1006.89 | N18: =SUMIF(Inventory!B:B,H18,Inventory!G:G) -> 364.7 | O18: =(N18/L18) -> 0.26589579 | Q18: =IFERROR(__xludf.DUMMYFUNCTION("SORTN({Inventory!A2:A7005, Inventory!G2:G7005, Inventory!B2:B7005, Inventory!D2:D7005}, 20, 0, Inventory!D2:D7005, False) "),"Worms Armageddon") -> Worms Armageddon | R18: =IFERROR(__xludf.DUMMYFUNCTION("""COMPUTED_VALUE"""),1.28) -> 1.28 | S18: =IFERROR(__xludf.DUMMYFUNCTION("""COMPUTED_VALUE"""),"G2A") -> G2A | T18: =IFERROR(__xludf.DUMMYFUNCTION("""COMPUTED_VALUE"""),46207.0) -> 46207
H19: Eneba | I19: =COUNTIF(Inventory!B:B,H19) -> 427 | J19: =COUNTIFS(Inventory!B:B,H19,Inventory!J:J,"Closed") -> 409 | K19: =(I19-J19) -> 18 | L19: =SUMIF(Inventory!B:B,H19,Inventory!F:F) -> 8127.36 | M19: =SUMIF(Inventory!B:B,H19,Inventory!E:E) -> 6947.45 | N19: =SUMIF(Inventory!B:B,H19,Inventory!G:G) -> 1179.91 | O19: =(N19/L19) -> 0.14517752 | Q19: =IFERROR(__xludf.DUMMYFUNCTION("""COMPUTED_VALUE"""),"Tempest Rising") -> Tempest Rising | R19: =IFERROR(__xludf.DUMMYFUNCTION("""COMPUTED_VALUE"""),5.16) -> 5.16 | S19: =IFERROR(__xludf.DUMMYFUNCTION("""COMPUTED_VALUE"""),"King") -> King | T19: =IFERROR(__xludf.DUMMYFUNCTION("""COMPUTED_VALUE"""),46205.0) -> 46205
A20: =IF(B20 > C20, "🟢", "🔴") -> 🔴 | B20: =IFERROR(SUMIFS(Inventory!F2:F7005, Inventory!D2:D7005, "="&TODAY(), Inventory!J2:J7005, "Closed") / COUNTIFS(Inventory!D2:D7005, "="&TODAY(), Inventory!J2:J7005, "Closed"), 0) -> 0 | C20: =SUMIFS(Inventory!F2:F7005, Inventory!D2:D7005, ">="&DATE(YEAR(TODAY()), MONTH(TODAY()), 1), Inventory!D2:D7005, "<="&EOMONTH(TODAY(), 0), Inventory!J2:J7005, "Closed") / COUNTIFS(Inventory!D2:D7005, ">="&DATE(YEAR(TODAY()), MONTH(TODAY()), 1), Inventory!D2:D7005, "<="&EOMONTH(TODAY(), 0), Inventory!J2:J7005, "Closed") -> 10.296667 | D20: =SUMIFS(Inventory!F2:F7005, Inventory!D2:D7005, ">="&TODAY()-WEEKDAY(TODAY(), 2)-7, Inventory!D2:D7005, "<="&TODAY()-WEEKDAY(TODAY(), 2)-1, Inventory!J2:J7005, "Closed") / COUNTIFS(Inventory!D2:D7005, ">="&TODAY()-WEEKDAY(TODAY(), 2)-7, Inventory!D2:D7005, "<="&TODAY()-WEEKDAY(TODAY(), 2)-1, Inventory!J2:J7005, "Closed") -> 13.807 | E20: =IFERROR(SUMIFS(Inventory!F2:F7005, Inventory!D2:D7005, "="&TODAY()-1, Inventory!J2:J7005, "Closed") / COUNTIFS(Inventory!D2:D7005, "="&TODAY()-1, Inventory!J2:J7005, "Closed"),0) -> 0 | H20: Fanatical | I20: =COUNTIF(Inventory!B:B,H20) -> 2295 | J20: =COUNTIFS(Inventory!B:B,H20,Inventory!J:J,"Closed") -> 2275 | K20: =(I20-J20) -> 20 | L20: =SUMIF(Inventory!B:B,H20,Inventory!F:F) -> 20919.141 | M20: =SUMIF(Inventory!B:B,H20,Inventory!E:E) -> 16186.38 | N20: =SUMIF(Inventory!B:B,H20,Inventory!G:G) -> 4732.761 | O20: =(N20/L20) -> 0.2262407 | Q20: =IFERROR(__xludf.DUMMYFUNCTION("""COMPUTED_VALUE"""),"Dead by Daylight") -> Dead by Daylight | R20: =IFERROR(__xludf.DUMMYFUNCTION("""COMPUTED_VALUE"""),5.0600000000000005) -> 5.06 | S20: =IFERROR(__xludf.DUMMYFUNCTION("""COMPUTED_VALUE"""),"G2A") -> G2A | T20: =IFERROR(__xludf.DUMMYFUNCTION("""COMPUTED_VALUE"""),46204.0) -> 46204
A21: SPNT | B21: =SUMIFS(Inventory!E2:E7005, Inventory!J2:J7005, "closed", Inventory!D2:D7005, "="&TODAY()) -> 0 | C21: =SUMIFS(Inventory!E2:E7005, Inventory!J2:J7005, "closed", Inventory!D2:D7005, ">="&DATE(YEAR(TODAY()), MONTH(TODAY()), 1), Inventory!D2:D7005, "<="&EOMONTH(TODAY(), 0)) -> 19.39 | D21: =SUMIFS(Inventory!E2:E7005, Inventory!J2:J7005, "closed", Inventory!D2:D7005, ">="&TODAY()-WEEKDAY(TODAY(), 2)-7, Inventory!D2:D7005, "<="&TODAY()-WEEKDAY(TODAY(), 2)-1) -> 95.5 | E21: =SUMIFS(Inventory!E2:E7005, Inventory!J2:J7005, "closed", Inventory!D2:D7005, "="&TODAY()-1) -> 0 | H21: Gamivo | I21: =COUNTIF(Inventory!B:B,H21) -> 802 | J21: =COUNTIFS(Inventory!B:B,H21,Inventory!J:J,"Closed") -> 741 | K21: =(I21-J21) -> 61 | L21: =SUMIF(Inventory!B:B,H21,Inventory!F:F) -> 16077.07 | M21: =SUMIF(Inventory!B:B,H21,Inventory!E:E) -> 14544.94 | N21: =SUMIF(Inventory!B:B,H21,Inventory!G:G) -> 1532.13 | O21: =(N21/L21) -> 0.095299081 | Q21: =IFERROR(__xludf.DUMMYFUNCTION("""COMPUTED_VALUE"""),"SoulQuest") -> SoulQuest | R21: =IFERROR(__xludf.DUMMYFUNCTION("""COMPUTED_VALUE"""),1.1500000000000004) -> 1.15 | S21: =IFERROR(__xludf.DUMMYFUNCTION("""COMPUTED_VALUE"""),"GreenMan") -> GreenMan | T21: =IFERROR(__xludf.DUMMYFUNCTION("""COMPUTED_VALUE"""),46203.0) -> 46203
H22: GreenMan | I22: =COUNTIF(Inventory!B:B,H22) -> 1458 | J22: =COUNTIFS(Inventory!B:B,H22,Inventory!J:J,"Closed") -> 1436 | K22: =(I22-J22) -> 22 | L22: =SUMIF(Inventory!B:B,H22,Inventory!F:F) -> 22532.81 | M22: =SUMIF(Inventory!B:B,H22,Inventory!E:E) -> 17434.526 | N22: =SUMIF(Inventory!B:B,H22,Inventory!G:G) -> 5098.2841 | O22: =(N22/L22) -> 0.22626047 | Q22: =IFERROR(__xludf.DUMMYFUNCTION("""COMPUTED_VALUE"""),"Dead by Daylight") -> Dead by Daylight | R22: =IFERROR(__xludf.DUMMYFUNCTION("""COMPUTED_VALUE"""),5.0600000000000005) -> 5.06 | S22: =IFERROR(__xludf.DUMMYFUNCTION("""COMPUTED_VALUE"""),"G2A") -> G2A | T22: =IFERROR(__xludf.DUMMYFUNCTION("""COMPUTED_VALUE"""),46203.0) -> 46203
A23: =IF(B23 < C23, "🟢", "🔴") -> 🟢 | B23: =IFERROR(SUMIFS(Inventory!E2:E7005, Inventory!D2:D7005, "="&TODAY(), Inventory!J2:J7005, "Closed") / COUNTIFS(Inventory!D2:D7005, "="&TODAY(), Inventory!J2:J7005, "Closed"), 0) -> 0 | C23: =SUMIFS(Inventory!E2:E7005, Inventory!D2:D7005, ">="&DATE(YEAR(TODAY()), MONTH(TODAY()), 1), Inventory!D2:D7005, "<="&EOMONTH(TODAY(), 0), Inventory!J2:J7005, "Closed") / COUNTIFS(Inventory!D2:D7005, ">="&DATE(YEAR(TODAY()), MONTH(TODAY()), 1), Inventory!D2:D7005, "<="&EOMONTH(TODAY(), 0), Inventory!J2:J7005, "Closed") -> 6.4633333 | D23: =SUMIFS(Inventory!E2:E7005, Inventory!D2:D7005, ">="&TODAY()-WEEKDAY(TODAY(), 2)-7, Inventory!D2:D7005, "<="&TODAY()-WEEKDAY(TODAY(), 2)-1, Inventory!J2:J7005, "Closed") / COUNTIFS(Inventory!D2:D7005, ">="&TODAY()-WEEKDAY(TODAY(), 2)-7, Inventory!D2:D7005, "<="&TODAY()-WEEKDAY(TODAY(), 2)-1, Inventory!J2:J7005, "Closed") -> 9.55 | E23: =IFERROR(SUMIFS(Inventory!E2:E7005, Inventory!D2:D7005, "="&TODAY()-1, Inventory!J2:J7005, "Closed") / COUNTIFS(Inventory!D2:D7005, "="&TODAY()-1, Inventory!J2:J7005, "Closed"),0) -> 0 | H23: GamesPlanet | I23: =COUNTIF(Inventory!B:B,H23) -> 597 | J23: =COUNTIFS(Inventory!B:B,H23,Inventory!J:J,"Closed") -> 587 | K23: =(I23-J23) -> 10 | L23: =SUMIF(Inventory!B:B,H23,Inventory!F:F) -> 9352.43 | M23: =SUMIF(Inventory!B:B,H23,Inventory!E:E) -> 7271.89 | N23: =SUMIF(Inventory!B:B,H23,Inventory!G:G) -> 2080.54 | O23: =(N23/L23) -> 0.22245983 | Q23: =IFERROR(__xludf.DUMMYFUNCTION("""COMPUTED_VALUE"""),"Dead by Daylight") -> Dead by Daylight | R23: =IFERROR(__xludf.DUMMYFUNCTION("""COMPUTED_VALUE"""),5.07) -> 5.07 | S23: =IFERROR(__xludf.DUMMYFUNCTION("""COMPUTED_VALUE"""),"G2A") -> G2A | T23: =IFERROR(__xludf.DUMMYFUNCTION("""COMPUTED_VALUE"""),46202.0) -> 46202
A24: PRFT | B24: =SUMIFS(Inventory!G2:G7005, Inventory!J2:J7005, "closed", Inventory!D2:D7005, "="&TODAY()) -> 0 | C24: =SUMIFS(Inventory!G2:G7005, Inventory!J2:J7005, "closed", Inventory!D2:D7005, ">="&DATE(YEAR(TODAY()), MONTH(TODAY()), 1), Inventory!D2:D7005, "<="&EOMONTH(TODAY(), 0)) -> 11.5 | D24: =SUMIFS(Inventory!G2:G7005, Inventory!J2:J7005, "closed", Inventory!D2:D7005, ">="&TODAY()-WEEKDAY(TODAY(), 2)-7, Inventory!D2:D7005, "<="&TODAY()-WEEKDAY(TODAY(), 2)-1) -> 42.57 | E24: =SUMIFS(Inventory!G2:G7005, Inventory!J2:J7005, "closed", Inventory!D2:D7005, "="&TODAY()-1) -> 0 | H24: G2A | I24: =COUNTIF(Inventory!B:B,H24) -> 716 | J24: =COUNTIFS(Inventory!B:B,H24,Inventory!J:J,"Closed") -> 688 | K24: =(I24-J24) -> 28 | L24: =SUMIF(Inventory!B:B,H24,Inventory!F:F) -> 11123.06 | M24: =SUMIF(Inventory!B:B,H24,Inventory!E:E) -> 9522.18 | N24: =SUMIF(Inventory!B:B,H24,Inventory!G:G) -> 1600.88 | O24: =(N24/L24) -> 0.14392442 | Q24: =IFERROR(__xludf.DUMMYFUNCTION("""COMPUTED_VALUE"""),"Sniper Elite 5 Deluxe Edition") -> Sniper Elite 5 Deluxe Edition | R24: =IFERROR(__xludf.DUMMYFUNCTION("""COMPUTED_VALUE"""),0.129999999999999) -> 0.13 | S24: =IFERROR(__xludf.DUMMYFUNCTION("""COMPUTED_VALUE"""),"K4G") -> K4G | T24: =IFERROR(__xludf.DUMMYFUNCTION("""COMPUTED_VALUE"""),46201.0) -> 46201
H25: IndieGala | I25: =COUNTIF(Inventory!B:B,H25) -> 23 | J25: =COUNTIFS(Inventory!B:B,H25,Inventory!J:J,"Closed") -> 22 | K25: =(I25-J25) -> 1 | L25: =SUMIF(Inventory!B:B,H25,Inventory!F:F) -> 131.66 | M25: =SUMIF(Inventory!B:B,H25,Inventory!E:E) -> 135.83 | N25: =SUMIF(Inventory!B:B,H25,Inventory!G:G) -> -4.17 | O25: =(N25/L25) -> -0.03167249 | Q25: =IFERROR(__xludf.DUMMYFUNCTION("""COMPUTED_VALUE"""),"Tempest Rising") -> Tempest Rising | R25: =IFERROR(__xludf.DUMMYFUNCTION("""COMPUTED_VALUE"""),6.16) -> 6.16 | S25: =IFERROR(__xludf.DUMMYFUNCTION("""COMPUTED_VALUE"""),"King") -> King | T25: =IFERROR(__xludf.DUMMYFUNCTION("""COMPUTED_VALUE"""),46201.0) -> 46201
A26: =IF(B26 > C26, "🟢", "🔴") -> 🔴 | B26: =IFERROR((SUMIFS(Inventory!F2:F7005, Inventory!D2:D7005, "="&TODAY(), Inventory!J2:J7005, "Closed") - SUMIFS(Inventory!E2:E7005, Inventory!D2:D7005, "="&TODAY(), Inventory!J2:J7005, "Closed")) / COUNTIFS(Inventory!D2:D7005, "="&TODAY(), Inventory!J2:J7005, "Closed"), 0) -> 0 | C26: =(SUMIFS(Inventory!F2:F7005, Inventory!D2:D7005, ">="&DATE(YEAR(TODAY()), MONTH(TODAY()), 1), Inventory!D2:D7005, "<="&EOMONTH(TODAY(), 0), Inventory!J2:J7005, "Closed") - SUMIFS(Inventory!E2:E7005, Inventory!D2:D7005, ">="&DATE(YEAR(TODAY()), MONTH(TODAY()), 1), Inventory!D2:D7005, "<="&EOMONTH(TODAY(), 0), Inventory!J2:J7005, "Closed")) / COUNTIFS(Inventory!D2:D7005, ">="&DATE(YEAR(TODAY()), MONTH(TODAY()), 1), Inventory!D2:D7005, "<="&EOMONTH(TODAY(), 0), Inventory!J2:J7005, "Closed") -> 3.8333333 | D26: =(SUMIFS(Inventory!F2:F7005, Inventory!D2:D7005, ">="&TODAY()-WEEKDAY(TODAY(), 2)-7, Inventory!D2:D7005, "<="&TODAY()-WEEKDAY(TODAY(), 2)-1, Inventory!J2:J7005, "Closed") - SUMIFS(Inventory!E2:E7005, Inventory!D2:D7005, ">="&TODAY()-WEEKDAY(TODAY(), 2)-7, Inventory!D2:D7005, "<="&TODAY()-WEEKDAY(TODAY(), 2)-1, Inventory!J2:J7005, "Closed")) / COUNTIFS(Inventory!D2:D7005, ">="&TODAY()-WEEKDAY(TODAY(), 2)-7, Inventory!D2:D7005, "<="&TODAY()-WEEKDAY(TODAY(), 2)-1, Inventory!J2:J7005, "Closed") -> 4.257 | E26: =IFERROR((SUMIFS(Inventory!F2:F7005, Inventory!D2:D7005, "="&TODAY()-1, Inventory!J2:J7005, "Closed") - SUMIFS(Inventory!E2:E7005, Inventory!D2:D7005, "="&TODAY()-1, Inventory!J2:J7005, "Closed")) / COUNTIFS(Inventory!D2:D7005, "="&TODAY()-1, Inventory!J2:J7005, "Closed"),0) -> 0 | H26: CDKeys | I26: =COUNTIF(Inventory!B:B,H26) -> 1797 | J26: =COUNTIFS(Inventory!B:B,H26,Inventory!J:J,"Closed") -> 1745 | K26: =(I26-J26) -> 52 | L26: =SUMIF(Inventory!B:B,H26,Inventory!F:F) -> 30579.94 | M26: =SUMIF(Inventory!B:B,H26,Inventory!E:E) -> 25908.24 | N26: =SUMIF(Inventory!B:B,H26,Inventory!G:G) -> 4671.7 | O26: =(N26/L26) -> 0.15277008 | Q26: =IFERROR(__xludf.DUMMYFUNCTION("""COMPUTED_VALUE"""),"Dead by Daylight") -> Dead by Daylight | R26: =IFERROR(__xludf.DUMMYFUNCTION("""COMPUTED_VALUE"""),6.75) -> 6.75 | S26: =IFERROR(__xludf.DUMMYFUNCTION("""COMPUTED_VALUE"""),"G2A") -> G2A | T26: =IFERROR(__xludf.DUMMYFUNCTION("""COMPUTED_VALUE"""),46201.0) -> 46201
A27: SOLD | B27: =COUNTIFS(Inventory!D2:D7005, "="&TODAY(), Inventory!J2:J7005, "Closed") -> 0 | C27: =COUNTIFS(Inventory!D2:D7005, ">="&DATE(YEAR(TODAY()), MONTH(TODAY()), 1), Inventory!D2:D7005, "<="&EOMONTH(TODAY(), 0), Inventory!J2:J7005, "Closed") -> 3 | D27: =COUNTIFS(Inventory!D2:D7005, ">="&TODAY()-WEEKDAY(TODAY(), 2)-7, Inventory!D2:D7005, "<="&TODAY()-WEEKDAY(TODAY(), 2)-1, Inventory!J2:J7005, "Closed") -> 10 | E27: =COUNTIFS(Inventory!D2:D7005, "="&TODAY()-1, Inventory!J2:J7005, "Closed") -> 0 | H27: King | I27: =COUNTIF(Inventory!B:B,H27) -> 173 | J27: =COUNTIFS(Inventory!B:B,H27,Inventory!J:J,"Closed") -> 147 | K27: =(I27-J27) -> 26 | L27: =SUMIF(Inventory!B:B,H27,Inventory!F:F) -> 2262.62 | M27: =SUMIF(Inventory!B:B,H27,Inventory!E:E) -> 1895.65 | N27: =SUMIF(Inventory!B:B,H27,Inventory!G:G) -> 366.97 | O27: =(N27/L27) -> 0.16218808 | Q27: =IFERROR(__xludf.DUMMYFUNCTION("""COMPUTED_VALUE"""),"Dead by Daylight") -> Dead by Daylight | R27: =IFERROR(__xludf.DUMMYFUNCTION("""COMPUTED_VALUE"""),6.75) -> 6.75 | S27: =IFERROR(__xludf.DUMMYFUNCTION("""COMPUTED_VALUE"""),"G2A") -> G2A | T27: =IFERROR(__xludf.DUMMYFUNCTION("""COMPUTED_VALUE"""),46201.0) -> 46201
H28: WinGame | I28: =COUNTIF(Inventory!B:B,H28) -> 117 | J28: =COUNTIFS(Inventory!B:B,H28,Inventory!J:J,"Closed") -> 116 | K28: =(I28-J28) -> 1 | L28: =SUMIF(Inventory!B:B,H28,Inventory!F:F) -> 1272.7 | M28: =SUMIF(Inventory!B:B,H28,Inventory!E:E) -> 1022.1 | N28: =SUMIF(Inventory!B:B,H28,Inventory!G:G) -> 250.6 | O28: =(N28/L28) -> 0.19690422 | Q28: =IFERROR(__xludf.DUMMYFUNCTION("""COMPUTED_VALUE"""),"Tempest Rising") -> Tempest Rising | R28: =IFERROR(__xludf.DUMMYFUNCTION("""COMPUTED_VALUE"""),6.16) -> 6.16 | S28: =IFERROR(__xludf.DUMMYFUNCTION("""COMPUTED_VALUE"""),"King") -> King | T28: =IFERROR(__xludf.DUMMYFUNCTION("""COMPUTED_VALUE"""),46200.0) -> 46200
A29: MRGN | B29: =IFERROR((B24/B18), 0) -> 0 | C29: =C24/C18 -> 0.37228877 | D29: =(D24/D18) -> 0.30832187 | E29: =(E24/E18) -> #DIV/0! | H29: K4G | I29: =COUNTIF(Inventory!B:B,H29) -> 174 | J29: =COUNTIFS(Inventory!B:B,H29,Inventory!J:J,"Closed") -> 152 | K29: =(I29-J29) -> 22 | L29: =SUMIF(Inventory!B:B,H29,Inventory!F:F) -> 2852.57 | M29: =SUMIF(Inventory!B:B,H29,Inventory!E:E) -> 2553.8 | N29: =SUMIF(Inventory!B:B,H29,Inventory!G:G) -> 298.77 | O29: =(N29/L29) -> 0.10473713 | Q29: =IFERROR(__xludf.DUMMYFUNCTION("""COMPUTED_VALUE"""),"Black Myth: Wukong") -> Black Myth: Wukong | R29: =IFERROR(__xludf.DUMMYFUNCTION("""COMPUTED_VALUE"""),1.8799999999999955) -> 1.88 | S29: =IFERROR(__xludf.DUMMYFUNCTION("""COMPUTED_VALUE"""),"CDKeys") -> CDKeys | T29: =IFERROR(__xludf.DUMMYFUNCTION("""COMPUTED_VALUE"""),46200.0) -> 46200
H30: InstGam | I30: =COUNTIF(Inventory!B:B,H30) -> 54 | J30: =COUNTIFS(Inventory!B:B,H30,Inventory!J:J,"Closed") -> 53 | K30: =(I30-J30) -> 1 | L30: =SUMIF(Inventory!B:B,H30,Inventory!F:F) -> 777.19 | M30: =SUMIF(Inventory!B:B,H30,Inventory!E:E) -> 598.69 | N30: =SUMIF(Inventory!B:B,H30,Inventory!G:G) -> 178.5 | O30: =(N30/L30) -> 0.22967357 | Q30: =IFERROR(__xludf.DUMMYFUNCTION("""COMPUTED_VALUE"""),"Tempest Rising") -> Tempest Rising | R30: =IFERROR(__xludf.DUMMYFUNCTION("""COMPUTED_VALUE"""),6.16) -> 6.16 | S30: =IFERROR(__xludf.DUMMYFUNCTION("""COMPUTED_VALUE"""),"King") -> King | T30: =IFERROR(__xludf.DUMMYFUNCTION("""COMPUTED_VALUE"""),46199.0) -> 46199
H31: HRK | I31: =COUNTIF(Inventory!B:B,H31) -> 5 | J31: =COUNTIFS(Inventory!B:B,H31,Inventory!J:J,"Closed") -> 4 | K31: =(I31-J31) -> 1 | L31: =SUMIF(Inventory!B:B,H31,Inventory!F:F) -> 69.3 | M31: =SUMIF(Inventory!B:B,H31,Inventory!E:E) -> 79.36 | N31: =SUMIF(Inventory!B:B,H31,Inventory!G:G) -> -10.06 | O31: =(N31/L31) -> -0.14516595 | Q31: =IFERROR(__xludf.DUMMYFUNCTION("""COMPUTED_VALUE"""),"Fallout 4 VR") -> Fallout 4 VR | R31: =IFERROR(__xludf.DUMMYFUNCTION("""COMPUTED_VALUE"""),1.9299999999999997) -> 1.93 | S31: =IFERROR(__xludf.DUMMYFUNCTION("""COMPUTED_VALUE"""),"CDKeys") -> CDKeys | T31: =IFERROR(__xludf.DUMMYFUNCTION("""COMPUTED_VALUE"""),46199.0) -> 46199
B32: RVN | C32: SPNT | D32: PRFT | E32: SOLD | F32: % | H32: GamersGate | I32: =COUNTIF(Inventory!B:B,H32) -> 44 | J32: =COUNTIFS(Inventory!B:B,H32,Inventory!J:J,"Closed") -> 43 | K32: =(I32-J32) -> 1 | L32: =SUMIF(Inventory!B:B,H32,Inventory!F:F) -> 387.16 | M32: =SUMIF(Inventory!B:B,H32,Inventory!E:E) -> 306.85 | N32: =SUMIF(Inventory!B:B,H32,Inventory!G:G) -> 80.31 | O32: =(N32/L32) -> 0.20743362 | Q32: =IFERROR(__xludf.DUMMYFUNCTION("""COMPUTED_VALUE"""),"Dead by Daylight") -> Dead by Daylight | R32: =IFERROR(__xludf.DUMMYFUNCTION("""COMPUTED_VALUE"""),6.760000000000002) -> 6.76 | S32: =IFERROR(__xludf.DUMMYFUNCTION("""COMPUTED_VALUE"""),"G2A") -> G2A | T32: =IFERROR(__xludf.DUMMYFUNCTION("""COMPUTED_VALUE"""),46199.0) -> 46199
A33: Mon | B33: =IFERROR(__xludf.DUMMYFUNCTION("SUM(FILTER(Inventory!F2:F7005, TEXT(Inventory!L2:L7005, ""ddd"")=A33))"),18426.07799999999) -> 18426.078 | C33: =IFERROR(__xludf.DUMMYFUNCTION("SUM(FILTER(Inventory!E2:E7005, TEXT(Inventory!L2:L7005, ""ddd"")=A33))"),14530.129999999976) -> 14530.13 | D33: =IFERROR(__xludf.DUMMYFUNCTION("SUM(FILTER(Inventory!G2:G7005, TEXT(Inventory!L2:L7005, ""ddd"")=A33))"),3895.948000000003) -> 3895.948 | E33: =COUNTIFS(Inventory!L:L, A33, Inventory!J:J, "Closed") -> 1156 | F33: =(E33*F47)/E47 -> 0.13273625 | H33: GamersOutlet | I33: =COUNTIF(Inventory!B:B,H33) -> 27 | J33: =COUNTIFS(Inventory!B:B,H33,Inventory!J:J,"Closed") -> 27 | K33: =(I33-J33) -> 0 | L33: =SUMIF(Inventory!B:B,H33,Inventory!F:F) -> 764.71 | M33: =SUMIF(Inventory!B:B,H33,Inventory!E:E) -> 617.22 | N33: =SUMIF(Inventory!B:B,H33,Inventory!G:G) -> 147.49 | O33: =(N33/L33) -> 0.1928705 | Q33: =IFERROR(__xludf.DUMMYFUNCTION("""COMPUTED_VALUE"""),"The Last of Us Part 2 Remastered") -> The Last of Us Part 2 Remastered | R33: =IFERROR(__xludf.DUMMYFUNCTION("""COMPUTED_VALUE"""),2.789999999999999) -> 2.79 | S33: =IFERROR(__xludf.DUMMYFUNCTION("""COMPUTED_VALUE"""),"CDKeys") -> CDKeys | T33: =IFERROR(__xludf.DUMMYFUNCTION("""COMPUTED_VALUE"""),46198.0) -> 46198
H34: MMOGA | I34: =COUNTIF(Inventory!B:B,H34) -> 53 | J34: =COUNTIFS(Inventory!B:B,H34,Inventory!J:J,"Closed") -> 49 | K34: =(I34-J34) -> 4 | L34: =SUMIF(Inventory!B:B,H34,Inventory!F:F) -> 986.37 | M34: =SUMIF(Inventory!B:B,H34,Inventory!E:E) -> 644.65 | N34: =SUMIF(Inventory!B:B,H34,Inventory!G:G) -> 341.72 | O34: =(N34/L34) -> 0.346442 | Q34: =IFERROR(__xludf.DUMMYFUNCTION("""COMPUTED_VALUE"""),"Manor Lords") -> Manor Lords | R34: =IFERROR(__xludf.DUMMYFUNCTION("""COMPUTED_VALUE"""),7.259999999999998) -> 7.26 | S34: =IFERROR(__xludf.DUMMYFUNCTION("""COMPUTED_VALUE"""),"CDKeys") -> CDKeys | T34: =IFERROR(__xludf.DUMMYFUNCTION("""COMPUTED_VALUE"""),46198.0) -> 46198
A35: Tue | B35: =IFERROR(__xludf.DUMMYFUNCTION("SUM(FILTER(Inventory!F2:F7005, TEXT(Inventory!L2:L7005, ""ddd"")=A35))"),15561.453000000007) -> 15561.453 | C35: =IFERROR(__xludf.DUMMYFUNCTION("SUM(FILTER(Inventory!E2:E7005, TEXT(Inventory!L2:L7005, ""ddd"")=A35))"),12204.610000000015) -> 12204.61 | D35: =IFERROR(__xludf.DUMMYFUNCTION("SUM(FILTER(Inventory!G2:G7005, TEXT(Inventory!L2:L7005, ""ddd"")=A35))"),3356.843) -> 3356.843 | E35: =COUNTIFS(Inventory!L:L, A35, Inventory!J:J, "Closed") -> 1041 | F35: =(E35*F47)/E47 -> 0.11953152 | H35: YuPlay | I35: =COUNTIF(Inventory!B:B,H35) -> 130 | J35: =COUNTIFS(Inventory!B:B,H35,Inventory!J:J,"Closed") -> 127 | K35: =(I35-J35) -> 3 | L35: =SUMIF(Inventory!B:B,H35,Inventory!F:F) -> 1746.1 | M35: =SUMIF(Inventory!B:B,H35,Inventory!E:E) -> 1376.72 | N35: =SUMIF(Inventory!B:B,H35,Inventory!G:G) -> 369.38 | O35: =(N35/L35) -> 0.21154573 | Q35: =IFERROR(__xludf.DUMMYFUNCTION("""COMPUTED_VALUE"""),"Sid Meier's Civilization VII EU") -> Sid Meier's Civilization VII EU | R35: =IFERROR(__xludf.DUMMYFUNCTION("""COMPUTED_VALUE"""),2.41) -> 2.41 | S35: =IFERROR(__xludf.DUMMYFUNCTION("""COMPUTED_VALUE"""),"CDKeys") -> CDKeys | T35: =IFERROR(__xludf.DUMMYFUNCTION("""COMPUTED_VALUE"""),46198.0) -> 46198
H36: Total | I36: =SUM(I18:I34) -> 8828 | J36: =SUM(J18:J34) -> 8559 | K36: =(I36-J36) -> 269 | L36: =SUM(L18:L34) -> 129587.68 | M36: =SUM(M18:M34) -> 106676.65 | N36: =SUM(N18:N34) -> 22911.035 | O36: =(N36/L36) -> 0.17679948 | Q36: =IFERROR(__xludf.DUMMYFUNCTION("""COMPUTED_VALUE"""),"Sid Meier's Civilization VII EU") -> Sid Meier's Civilization VII EU | R36: =IFERROR(__xludf.DUMMYFUNCTION("""COMPUTED_VALUE"""),2.41) -> 2.41 | S36: =IFERROR(__xludf.DUMMYFUNCTION("""COMPUTED_VALUE"""),"CDKeys") -> CDKeys | T36: =IFERROR(__xludf.DUMMYFUNCTION("""COMPUTED_VALUE"""),46198.0) -> 46198
A37: Wed | B37: =IFERROR(__xludf.DUMMYFUNCTION("SUM(FILTER(Inventory!F2:F7005, TEXT(Inventory!L2:L7005, ""ddd"")=A37))"),15543.910000000014) -> 15543.91 | C37: =IFERROR(__xludf.DUMMYFUNCTION("SUM(FILTER(Inventory!E2:E7005, TEXT(Inventory!L2:L7005, ""ddd"")=A37))"),12169.109999999975) -> 12169.11 | D37: =IFERROR(__xludf.DUMMYFUNCTION("SUM(FILTER(Inventory!G2:G7005, TEXT(Inventory!L2:L7005, ""ddd"")=A37))"),3374.8000000000034) -> 3374.8 | E37: =COUNTIFS(Inventory!L:L, A37, Inventory!J:J, "Closed") -> 1065 | F37: =(E37*F47)/E47 -> 0.12228729 | Q37: =IFERROR(__xludf.DUMMYFUNCTION("""COMPUTED_VALUE"""),"Sid Meier's Civilization VII EU") -> Sid Meier's Civilization VII EU | R37: =IFERROR(__xludf.DUMMYFUNCTION("""COMPUTED_VALUE"""),2.3099999999999987) -> 2.31 | S37: =IFERROR(__xludf.DUMMYFUNCTION("""COMPUTED_VALUE"""),"CDKeys") -> CDKeys | T37: =IFERROR(__xludf.DUMMYFUNCTION("""COMPUTED_VALUE"""),46198.0) -> 46198
A39: Thu | B39: =IFERROR(__xludf.DUMMYFUNCTION("SUM(FILTER(Inventory!F2:F7005, TEXT(Inventory!L2:L7005, ""ddd"")=A39))"),16474.30999999999) -> 16474.31 | C39: =IFERROR(__xludf.DUMMYFUNCTION("SUM(FILTER(Inventory!E2:E7005, TEXT(Inventory!L2:L7005, ""ddd"")=A39))"),13076.360000000006) -> 13076.36 | D39: =IFERROR(__xludf.DUMMYFUNCTION("SUM(FILTER(Inventory!G2:G7005, TEXT(Inventory!L2:L7005, ""ddd"")=A39))"),3397.950000000002) -> 3397.95 | E39: =COUNTIFS(Inventory!L:L, A39, Inventory!J:J, "Closed") -> 1072 | F39: =(E39*F47)/E47 -> 0.12309106 | H39: KEYS
H40: ALL | I40: OPEN | J40: COST | K40: CLOSED
A41: Fri | B41: =IFERROR(__xludf.DUMMYFUNCTION("SUM(FILTER(Inventory!F2:F7005, TEXT(Inventory!L2:L7005, ""ddd"")=A41))"),18772.299999999985) -> 18772.3 | C41: =IFERROR(__xludf.DUMMYFUNCTION("SUM(FILTER(Inventory!E2:E7005, TEXT(Inventory!L2:L7005, ""ddd"")=A41))"),14913.389999999976) -> 14913.39 | D41: =IFERROR(__xludf.DUMMYFUNCTION("SUM(FILTER(Inventory!G2:G7005, TEXT(Inventory!L2:L7005, ""ddd"")=A41))"),3862.299999999993) -> 3862.3 | E41: =COUNTIFS(Inventory!L:L, A41, Inventory!J:J, "Closed") -> 1240 | F41: =(E41*F47)/E47 -> 0.14238144 | I41: =COUNTIF(Inventory!J:J,I40) -> 263 | J41: =SUMIF(Inventory!J:J,I40,Inventory!E:E) -> 4305.18 | K41: =COUNTIF(Inventory!J:J,K40) -> 8709
A43: Sat | B43: =IFERROR(__xludf.DUMMYFUNCTION("SUM(FILTER(Inventory!F2:F7005, TEXT(Inventory!L2:L7005, ""ddd"")=A43))"),23987.738000000023) -> 23987.738 | C43: =IFERROR(__xludf.DUMMYFUNCTION("SUM(FILTER(Inventory!E2:E7005, TEXT(Inventory!L2:L7005, ""ddd"")=A43))"),19040.433730158766) -> 19040.434 | D43: =IFERROR(__xludf.DUMMYFUNCTION("SUM(FILTER(Inventory!G2:G7005, TEXT(Inventory!L2:L7005, ""ddd"")=A43))"),4947.304269841263) -> 4947.3043 | E43: =COUNTIFS(Inventory!L:L, A43, Inventory!J:J, "Closed") -> 1559 | F43: =(E43*F47)/E47 -> 0.17901022 | H43: 2022 | I43: =COUNTIFS(Inventory!J:J, "Open",Inventory!C:C, ">="&DATE(2022,1,1), Inventory!C:C, "<="&DATE(2022,12,31)) -> 11 | J43: =SUMIFS(Inventory!E:E, Inventory!J:J, "Open", Inventory!C:C, ">="&DATE(2022,1,1), Inventory!C:C, "<="&DATE(2022,12,31)) -> 185.92
A45: Sun | B45: =IFERROR(__xludf.DUMMYFUNCTION("SUM(FILTER(Inventory!F2:F7005, TEXT(Inventory!L2:L7005, ""ddd"")=A45))"),23410.980000000036) -> 23410.98 | C45: =IFERROR(__xludf.DUMMYFUNCTION("SUM(FILTER(Inventory!E2:E7005, TEXT(Inventory!L2:L7005, ""ddd"")=A45))"),18485.99214285714) -> 18485.992 | D45: =IFERROR(__xludf.DUMMYFUNCTION("SUM(FILTER(Inventory!G2:G7005, TEXT(Inventory!L2:L7005, ""ddd"")=A45))"),4928.377857142853) -> 4928.3779 | E45: =COUNTIFS(Inventory!L:L, A45, Inventory!J:J, "Closed") -> 1576 | F45: =(E45*F47)/E47 -> 0.18096222 | H45: 2023 | I45: =COUNTIFS(Inventory!J:J, "Open",Inventory!C:C, ">="&DATE(2023,1,1), Inventory!C:C, "<="&DATE(2023,12,31)) -> 73 | J45: =SUMIFS(Inventory!E:E, Inventory!J:J, "Open", Inventory!C:C, ">="&DATE(2023,1,1), Inventory!C:C, "<="&DATE(2023,12,31)) -> 1166.7
A47: TTL | B47: =sum(B33:B46) -> 132176.77 | C47: =sum(C33:C46) -> 104420.03 | D47: =sum(D33:D46) -> 27763.523 | E47: =sum(E33:E46) -> 8709 | F47: 1 | H47: 2024 | I47: =COUNTIFS(Inventory!J:J, "Open",Inventory!C:C, ">="&DATE(2024,1,1), Inventory!C:C, "<="&DATE(2024,12,31)) -> 40 | J47: =SUMIFS(Inventory!E:E, Inventory!J:J, "Open", Inventory!C:C, ">="&DATE(2024,1,1), Inventory!C:C, "<="&DATE(2024,12,31)) -> 708.31
H49: 2025 | I49: =COUNTIFS(Inventory!J:J, "Open",Inventory!C:C, ">="&DATE(2025,1,1), Inventory!C:C, "<="&DATE(2025,12,31)) -> 38 | J49: =SUMIFS(Inventory!E:E, Inventory!J:J, "Open", Inventory!C:C, ">="&DATE(2025,1,1), Inventory!C:C, "<="&DATE(2025,12,31)) -> 666.79
B50: Profit | C50: Revenue | D50: Margin
A51: {=SEQUENCE(DAY(EOMONTH(TODAY(), 0)), 1, DATE(YEAR(TODAY()), MONTH(TODAY()), 1))} -> 46204 | B51: =IF(AND(A51<=EOMONTH(TODAY(),0), A51<=TODAY()), IF(SUMIFS(Inventory!G:G, Inventory!D:D, A51, Inventory!J:J, "closed")=0, "", SUMIFS(Inventory!G:G, Inventory!D:D, A51, Inventory!J:J, "closed")), "") -> 5.06 | C51: =IF(AND(A51<=EOMONTH(TODAY(),0), A51<=TODAY()), IF(SUMIFS(Inventory!F:F, Inventory!D:D, A51, Inventory!J:J, "closed")=0, "", SUMIFS(Inventory!F:F, Inventory!D:D, A51, Inventory!J:J, "closed")), "") -> 19.46 | H51: 2026 | I51: =COUNTIFS(Inventory!J:J, "Open",Inventory!C:C, ">="&DATE(2026,1,1), Inventory!C:C, "<="&DATE(2026,12,31)) -> 99 | J51: =SUMIFS(Inventory!E:E, Inventory!J:J, "Open", Inventory!C:C, ">="&DATE(2026,1,1), Inventory!C:C, "<="&DATE(2026,12,31)) -> 1563.16
A52: 46205 | B52: =IF(AND(A52<=EOMONTH(TODAY(),0), A52<=TODAY()), IF(SUMIFS(Inventory!G:G, Inventory!D:D, A52, Inventory!J:J, "closed")=0, "", SUMIFS(Inventory!G:G, Inventory!D:D, A52, Inventory!J:J, "closed")), "") -> 5.16 | C52: =IF(AND(A52<=EOMONTH(TODAY(),0), A52<=TODAY()), IF(SUMIFS(Inventory!F:F, Inventory!D:D, A52, Inventory!J:J, "closed")=0, "", SUMIFS(Inventory!F:F, Inventory!D:D, A52, Inventory!J:J, "closed")), "") -> 10.15
A53: 46206 | B53: =IF(AND(A53<=EOMONTH(TODAY(),0), A53<=TODAY()), IF(SUMIFS(Inventory!G:G, Inventory!D:D, A53, Inventory!J:J, "closed")=0, "", SUMIFS(Inventory!G:G, Inventory!D:D, A53, Inventory!J:J, "closed")), "") | C53: =IF(AND(A53<=EOMONTH(TODAY(),0), A53<=TODAY()), IF(SUMIFS(Inventory!F:F, Inventory!D:D, A53, Inventory!J:J, "closed")=0, "", SUMIFS(Inventory!F:F, Inventory!D:D, A53, Inventory!J:J, "closed")), "")
A54: 46207 | B54: =IF(AND(A54<=EOMONTH(TODAY(),0), A54<=TODAY()), IF(SUMIFS(Inventory!G:G, Inventory!D:D, A54, Inventory!J:J, "closed")=0, "", SUMIFS(Inventory!G:G, Inventory!D:D, A54, Inventory!J:J, "closed")), "") -> 1.28 | C54: =IF(AND(A54<=EOMONTH(TODAY(),0), A54<=TODAY()), IF(SUMIFS(Inventory!F:F, Inventory!D:D, A54, Inventory!J:J, "closed")=0, "", SUMIFS(Inventory!F:F, Inventory!D:D, A54, Inventory!J:J, "closed")), "") -> 1.28
A55: 46208 | B55: =IF(AND(A55<=EOMONTH(TODAY(),0), A55<=TODAY()), IF(SUMIFS(Inventory!G:G, Inventory!D:D, A55, Inventory!J:J, "closed")=0, "", SUMIFS(Inventory!G:G, Inventory!D:D, A55, Inventory!J:J, "closed")), "") | C55: =IF(AND(A55<=EOMONTH(TODAY(),0), A55<=TODAY()), IF(SUMIFS(Inventory!F:F, Inventory!D:D, A55, Inventory!J:J, "closed")=0, "", SUMIFS(Inventory!F:F, Inventory!D:D, A55, Inventory!J:J, "closed")), "")
A56: 46209 | B56: =IF(AND(A56<=EOMONTH(TODAY(),0), A56<=TODAY()), IF(SUMIFS(Inventory!G:G, Inventory!D:D, A56, Inventory!J:J, "closed")=0, "", SUMIFS(Inventory!G:G, Inventory!D:D, A56, Inventory!J:J, "closed")), "") | C56: =IF(AND(A56<=EOMONTH(TODAY(),0), A56<=TODAY()), IF(SUMIFS(Inventory!F:F, Inventory!D:D, A56, Inventory!J:J, "closed")=0, "", SUMIFS(Inventory!F:F, Inventory!D:D, A56, Inventory!J:J, "closed")), "")
A57: 46210 | B57: =IF(AND(A57<=EOMONTH(TODAY(),0), A57<=TODAY()), IF(SUMIFS(Inventory!G:G, Inventory!D:D, A57, Inventory!J:J, "closed")=0, "", SUMIFS(Inventory!G:G, Inventory!D:D, A57, Inventory!J:J, "closed")), "") | C57: =IF(AND(A57<=EOMONTH(TODAY(),0), A57<=TODAY()), IF(SUMIFS(Inventory!F:F, Inventory!D:D, A57, Inventory!J:J, "closed")=0, "", SUMIFS(Inventory!F:F, Inventory!D:D, A57, Inventory!J:J, "closed")), "")
A58: 46211 | B58: =IF(AND(A58<=EOMONTH(TODAY(),0), A58<=TODAY()), IF(SUMIFS(Inventory!G:G, Inventory!D:D, A58, Inventory!J:J, "closed")=0, "", SUMIFS(Inventory!G:G, Inventory!D:D, A58, Inventory!J:J, "closed")), "") | C58: =IF(AND(A58<=EOMONTH(TODAY(),0), A58<=TODAY()), IF(SUMIFS(Inventory!F:F, Inventory!D:D, A58, Inventory!J:J, "closed")=0, "", SUMIFS(Inventory!F:F, Inventory!D:D, A58, Inventory!J:J, "closed")), "")
A59: 46212 | B59: =IF(AND(A59<=EOMONTH(TODAY(),0), A59<=TODAY()), IF(SUMIFS(Inventory!G:G, Inventory!D:D, A59, Inventory!J:J, "closed")=0, "", SUMIFS(Inventory!G:G, Inventory!D:D, A59, Inventory!J:J, "closed")), "") | C59: =IF(AND(A59<=EOMONTH(TODAY(),0), A59<=TODAY()), IF(SUMIFS(Inventory!F:F, Inventory!D:D, A59, Inventory!J:J, "closed")=0, "", SUMIFS(Inventory!F:F, Inventory!D:D, A59, Inventory!J:J, "closed")), "")
A60: 46213 | B60: =IF(AND(A60<=EOMONTH(TODAY(),0), A60<=TODAY()), IF(SUMIFS(Inventory!G:G, Inventory!D:D, A60, Inventory!J:J, "closed")=0, "", SUMIFS(Inventory!G:G, Inventory!D:D, A60, Inventory!J:J, "closed")), "") | C60: =IF(AND(A60<=EOMONTH(TODAY(),0), A60<=TODAY()), IF(SUMIFS(Inventory!F:F, Inventory!D:D, A60, Inventory!J:J, "closed")=0, "", SUMIFS(Inventory!F:F, Inventory!D:D, A60, Inventory!J:J, "closed")), "")
...

Sheet Inventory
A1: Name | B1: Vendor | C1: Entry Date | D1: Closed Date | E1: Cost | F1: Sell | G1: Profit | H1: Margin | I1: Key | J1: Status | K1: Duration | L1: Day | M1: Publisher | N1: Img | O1: LP
A2: Bayonetta RoW | B2: Other | C2: 43949 | D2: 43953 | E2: 4.25 | F2: 5.55 | G2: =MINUS(F2,E2) -> 1.3 | H2: =IFERROR(G2/F2,"") -> 0.23423423 | I2: P3KXY-4C6G3-9B8A6 | J2: Closed | K2: =IFERROR(DATEDIF(C2,D2,"D"), "") -> 4 | L2: =IF(D2="","",TEXT(D2,"DDD")) -> Sat | M2: =IFERROR(VLOOKUP(A2, Entries!A:B,2,false),"") -> SEGA | N2: =IFERROR(VLOOKUP(A2, Entries!A:K,11,false),"") | O2: =IFERROR(VLOOKUP(A2, Entries!A:I,8,false),"") -> FALSE
A3: Bayonetta RoW | B3: Other | C3: 43949 | D3: 43960 | E3: 4.25 | F3: 5.05 | G3: =MINUS(F3,E3) -> 0.8 | H3: =IFERROR(G3/F3,"") -> 0.15841584 | I3: BRNIJ-ECE0I-HYGEM | J3: Closed | K3: =IFERROR(DATEDIF(C3,D3,"D"), "") -> 11 | L3: =IF(D3="","",TEXT(D3,"DDD")) -> Sat | M3: =IFERROR(VLOOKUP(A3, Entries!A:B,2,false),"") -> SEGA | N3: =IFERROR(VLOOKUP(A3, Entries!A:K,11,false),"") | O3: =IFERROR(VLOOKUP(A3, Entries!A:I,8,false),"") -> FALSE
A4: Bayonetta RoW | B4: Other | C4: 43949 | D4: 43962 | E4: 4.25 | F4: 5.72 | G4: =MINUS(F4,E4) -> 1.47 | H4: =IFERROR(G4/F4,"") -> 0.25699301 | I4: J2TZF-N4V43-LKJNN | J4: Closed | K4: =IFERROR(DATEDIF(C4,D4,"D"), "") -> 13 | L4: =IF(D4="","",TEXT(D4,"DDD")) -> Mon | M4: =IFERROR(VLOOKUP(A4, Entries!A:B,2,false),"") -> SEGA | N4: =IFERROR(VLOOKUP(A4, Entries!A:K,11,false),"") | O4: =IFERROR(VLOOKUP(A4, Entries!A:I,8,false),"") -> FALSE
A5: Bayonetta RoW | B5: Other | C5: 43949 | D5: 43967 | E5: 4.19 | F5: 5.93 | G5: =MINUS(F5,E5) -> 1.74 | H5: =IFERROR(G5/F5,"") -> 0.29342327 | I5: 9L354-YT0MY-GT40T | J5: Closed | K5: =IFERROR(DATEDIF(C5,D5,"D"), "") -> 18 | L5: =IF(D5="","",TEXT(D5,"DDD")) -> Sat | M5: =IFERROR(VLOOKUP(A5, Entries!A:B,2,false),"") -> SEGA | N5: =IFERROR(VLOOKUP(A5, Entries!A:K,11,false),"") | O5: =IFERROR(VLOOKUP(A5, Entries!A:I,8,false),"") -> FALSE
A6: LEGO: Marvel Super Heroes 2 (Deluxe Edition) | B6: Eneba | C6: 43949 | D6: 43952 | E6: 7.16 | F6: 8.34 | G6: =MINUS(F6,E6) -> 1.18 | H6: =IFERROR(G6/F6,"") -> 0.14148681 | I6: BA2EG-4JTEV-W8TN8 | J6: Closed | K6: =IFERROR(DATEDIF(C6,D6,"D"), "") -> 3 | L6: =IF(D6="","",TEXT(D6,"DDD")) -> Fri | M6: =IFERROR(VLOOKUP(A6, Entries!A:B,2,false),"") -> Warner Bros | N6: =IFERROR(VLOOKUP(A6, Entries!A:K,11,false),"") | O6: =IFERROR(VLOOKUP(A6, Entries!A:I,8,false),"") -> FALSE
A7: Shadow of the Tomb Raider Definitive Edition | B7: Fanatical | C7: 43949 | D7: 43949 | E7: 16.19 | F7: 18.3 | G7: =MINUS(F7,E7) -> 2.11 | H7: =IFERROR(G7/F7,"") -> 0.11530055 | I7: XHVTQ-45RXF-TQLF9 | J7: Closed | K7: =IFERROR(DATEDIF(C7,D7,"D"), "") -> 0 | L7: =IF(D7="","",TEXT(D7,"DDD")) -> Tue | M7: =IFERROR(VLOOKUP(A7, Entries!A:B,2,false),"") -> Square Enix | N7: =IFERROR(VLOOKUP(A7, Entries!A:K,11,false),"") | O7: =IFERROR(VLOOKUP(A7, Entries!A:I,8,false),"") -> TRUE
A8: Shadow of the Tomb Raider Definitive Edition | B8: Fanatical | C8: 43949 | D8: 43950 | E8: 16.19 | F8: 18.3 | G8: =MINUS(F8,E8) -> 2.11 | H8: =IFERROR(G8/F8,"") -> 0.11530055 | I8: J83FK-3N60R-DKDE4 | J8: Closed | K8: =IFERROR(DATEDIF(C8,D8,"D"), "") -> 1 | L8: =IF(D8="","",TEXT(D8,"DDD")) -> Wed | M8: =IFERROR(VLOOKUP(A8, Entries!A:B,2,false),"") -> Square Enix | N8: =IFERROR(VLOOKUP(A8, Entries!A:K,11,false),"") | O8: =IFERROR(VLOOKUP(A8, Entries!A:I,8,false),"") -> TRUE
A9: NBA 2K20 | B9: Gamivo | C9: 43950 | D9: 43982 | E9: 13.42 | F9: 14.71 | G9: =MINUS(F9,E9) -> 1.29 | H9: =IFERROR(G9/F9,"") -> 0.087695445 | I9: 36MW7-4HZQT-ZAM27 | J9: Closed | K9: =IFERROR(DATEDIF(C9,D9,"D"), "") -> 32 | L9: =IF(D9="","",TEXT(D9,"DDD")) -> Sun | M9: =IFERROR(VLOOKUP(A9, Entries!A:B,2,false),"") -> 2K | N9: =IFERROR(VLOOKUP(A9, Entries!A:K,11,false),"") | O9: =IFERROR(VLOOKUP(A9, Entries!A:I,8,false),"") -> FALSE
A10: NBA 2K20 | B10: Gamivo | C10: 43950 | D10: 43982 | E10: 13.41 | F10: 15.15 | G10: =MINUS(F10,E10) -> 1.74 | H10: =IFERROR(G10/F10,"") -> 0.11485149 | I10: 34MZM-H02ZH-2YV04 | J10: Closed | K10: =IFERROR(DATEDIF(C10,D10,"D"), "") -> 32 | L10: =IF(D10="","",TEXT(D10,"DDD")) -> Sun | M10: =IFERROR(VLOOKUP(A10, Entries!A:B,2,false),"") -> 2K | N10: =IFERROR(VLOOKUP(A10, Entries!A:K,11,false),"") | O10: =IFERROR(VLOOKUP(A10, Entries!A:I,8,false),"") -> FALSE
A11: NBA 2K20 | B11: Gamivo | C11: 43950 | D11: 43953 | E11: 13.5 | F11: 16.05 | G11: =MINUS(F11,E11) -> 2.55 | H11: =IFERROR(G11/F11,"") -> 0.1588785 | I11: F7NZG-FB4W5-ZV8P6 | J11: Closed | K11: =IFERROR(DATEDIF(C11,D11,"D"), "") -> 3 | L11: =IF(D11="","",TEXT(D11,"DDD")) -> Sat | M11: =IFERROR(VLOOKUP(A11, Entries!A:B,2,false),"") -> 2K | N11: =IFERROR(VLOOKUP(A11, Entries!A:K,11,false),"") | O11: =IFERROR(VLOOKUP(A11, Entries!A:I,8,false),"") -> FALSE
A12: NBA 2K20 | B12: Gamivo | C12: 43950 | D12: 43961 | E12: 13.5 | F12: 15.6 | G12: =MINUS(F12,E12) -> 2.1 | H12: =IFERROR(G12/F12,"") -> 0.13461538 | I12: CMTB2-R49K2-FZBZD | J12: Closed | K12: =IFERROR(DATEDIF(C12,D12,"D"), "") -> 11 | L12: =IF(D12="","",TEXT(D12,"DDD")) -> Sun | M12: =IFERROR(VLOOKUP(A12, Entries!A:B,2,false),"") -> 2K | N12: =IFERROR(VLOOKUP(A12, Entries!A:K,11,false),"") | O12: =IFERROR(VLOOKUP(A12, Entries!A:I,8,false),"") -> FALSE
A13: NBA 2K20 | B13: Gamivo | C13: 43950 | D13: 43982 | E13: 13.6 | F13: 15.15 | G13: =MINUS(F13,E13) -> 1.55 | H13: =IFERROR(G13/F13,"") -> 0.10231023 | I13: C7YC5-8NIY6-J08LW | J13: Closed | K13: =IFERROR(DATEDIF(C13,D13,"D"), "") -> 32 | L13: =IF(D13="","",TEXT(D13,"DDD")) -> Sun | M13: =IFERROR(VLOOKUP(A13, Entries!A:B,2,false),"") -> 2K | N13: =IFERROR(VLOOKUP(A13, Entries!A:K,11,false),"") | O13: =IFERROR(VLOOKUP(A13, Entries!A:I,8,false),"") -> FALSE
... A792: Overload | B792: Gamivo | C792: 44322 | D792: 44375 | E792: 0.35 | F792: 0.42 | G792: =MINUS(F792,E792) -> 0.07 | H792: =IFERROR(G792/F792,"") -> 0.16666667 | I792: 3XEXV-TEABP-K7NYL | J792: Closed | K792: =IFERROR(DATEDIF(C792,D792,"D"), "") -> 53 | L792: =IF(D792="","",TEXT(D792,"DDD")) -> Mon | M792: =IFERROR(VLOOKUP(A792, Entries!A:B,2,false),"") -> Revival Productions | N792: =IFERROR(VLOOKUP(A792, Entries!A:K,11,false),"") | O792: =IFERROR(VLOOKUP(A792, Entries!A:I,8,false),"") -> FALSE
A793: Overload | B793: Gamivo | C793: 44322 | E793: 0.35 | G793: =MINUS(F793,E793) -> -0.35 | H793: =IFERROR(G793/F793,"") | J793: Rejected | K793: =IFERROR(DATEDIF(C793,D793,"D"), "") | L793: =IF(D793="","",TEXT(D793,"DDDD")) | M793: =IFERROR(VLOOKUP(A793, Unique!A:E,5,false),"")
A794: Shadow of the Tomb Raider Definitive Edition | B794: Fanatical | C794: 44323 | D794: 44324 | E794: 11.38 | F794: 13.92 | G794: =MINUS(F794,E794) -> 2.54 | H794: =IFERROR(G794/F794,"") -> 0.18247126 | I794: W2RBY-R8J86-ZCZWT | J794: Closed | K794: =IFERROR(DATEDIF(C794,D794,"D"), "") -> 1 | L794: =IF(D794="","",TEXT(D794,"DDD")) -> Sat | M794: =IFERROR(VLOOKUP(A794, Entries!A:B,2,false),"") -> Square Enix | N794: =IFERROR(VLOOKUP(A794, Entries!A:K,11,false),"") | O794: =IFERROR(VLOOKUP(A794, Entries!A:I,8,false),"") -> TRUE
A795: Shadow of the Tomb Raider Definitive Edition | B795: Fanatical | C795: 44323 | D795: 44326 | E795: 11.38 | F795: 13.93 | G795: =MINUS(F795,E795) -> 2.55 | H795: =IFERROR(G795/F795,"") -> 0.18305815 | I795: E6T4B-GXFGX-7PEPZ | J795: Closed | K795: =IFERROR(DATEDIF(C795,D795,"D"), "") -> 3 | L795: =IF(D795="","",TEXT(D795,"DDD")) -> Mon | M795: =IFERROR(VLOOKUP(A795, Entries!A:B,2,false),"") -> Square Enix | N795: =IFERROR(VLOOKUP(A795, Entries!A:K,11,false),"") | O795: =IFERROR(VLOOKUP(A795, Entries!A:I,8,false),"") -> TRUE
A796: Transport Fever 2 | B796: GamesPlanet | C796: 44324 | D796: 44324 | E796: 18.24 | F796: 23.01 | G796: =MINUS(F796,E796) -> 4.77 | H796: =IFERROR(G796/F796,"") -> 0.20730117 | I796: HWGLI-N6YI5-N0L50 | J796: Closed | K796: =IFERROR(DATEDIF(C796,D796,"D"), "") -> 0 | L796: =IF(D796="","",TEXT(D796,"DDD")) -> Sat | M796: =IFERROR(VLOOKUP(A796, Entries!A:B,2,false),"") -> Good Shepherd Entertainment | N796: =IFERROR(VLOOKUP(A796, Entries!A:K,11,false),"") | O796: =IFERROR(VLOOKUP(A796, Entries!A:I,8,false),"") -> FALSE
A797: Transport Fever 2 | B797: GamesPlanet | C797: 44324 | D797: 44327 | E797: 18.24 | F797: 22.24 | G797: =MINUS(F797,E797) -> 4 | H797: =IFERROR(G797/F797,"") -> 0.17985612 | I797: 8PJMA-QAXFC-60EC3 | J797: Closed | K797: =IFERROR(DATEDIF(C797,D797,"D"), "") -> 3 | L797: =IF(D797="","",TEXT(D797,"DDD")) -> Tue | M797: =IFERROR(VLOOKUP(A797, Entries!A:B,2,false),"") -> Good Shepherd Entertainment | N797: =IFERROR(VLOOKUP(A797, Entries!A:K,11,false),"") | O797: =IFERROR(VLOOKUP(A797, Entries!A:I,8,false),"") -> FALSE
A798: Shadow of the Tomb Raider Definitive Edition | B798: Fanatical | C798: 44324 | D798: 44329 | E798: 11.32 | F798: 15.85 | G798: =MINUS(F798,E798) -> 4.53 | H798: =IFERROR(G798/F798,"") -> 0.28580442 | I798: GN46P-MKI5L-CFQ37 | J798: Closed | K798: =IFERROR(DATEDIF(C798,D798,"D"), "") -> 5 | L798: =IF(D798="","",TEXT(D798,"DDD")) -> Thu | M798: =IFERROR(VLOOKUP(A798, Entries!A:B,2,false),"") -> Square Enix | N798: =IFERROR(VLOOKUP(A798, Entries!A:K,11,false),"") | O798: =IFERROR(VLOOKUP(A798, Entries!A:I,8,false),"") -> TRUE
A799: Praetorians HD Remaster | B799: Fanatical | C799: 44324 | D799: 44326 | E799: 2.88 | F799: 3.76 | G799: =MINUS(F799,E799) -> 0.88 | H799: =IFERROR(G799/F799,"") -> 0.23404255 | I799: DHJ8H-FGEWX-6XW9V | J799: Closed | K799: =IFERROR(DATEDIF(C799,D799,"D"), "") -> 2 | L799: =IF(D799="","",TEXT(D799,"DDD")) -> Mon | M799: =IFERROR(VLOOKUP(A799, Entries!A:B,2,false),"") -> Kalypso Media | N799: =IFERROR(VLOOKUP(A799, Entries!A:K,11,false),"") | O799: =IFERROR(VLOOKUP(A799, Entries!A:I,8,false),"") -> FALSE
A800: DiRT Rally 2.0 Game of the Year Edition | B800: Fanatical | C800: 44324 | D800: 44324 | E800: 2.88 | F800: 4.28 | G800: =MINUS(F800,E800) -> 1.4 | H800: =IFERROR(G800/F800,"") -> 0.3271028 | I800: Img | J800: Closed | K800: =IFERROR(DATEDIF(C800,D800,"D"), "") -> 0 | L800: =IF(D800="","",TEXT(D800,"DDD")) -> Sat | M800: =IFERROR(VLOOKUP(A800, Entries!A:B,2,false),"") -> Codemasters | N800: =IFERROR(VLOOKUP(A800, Entries!A:K,11,false),"") | O800: =IFERROR(VLOOKUP(A800, Entries!A:I,8,false),"") -> FALSE
A801: Verdun | B801: Fanatical | C801: 44324 | D801: 44326 | E801: 2.87 | F801: 3.72 | G801: =MINUS(F801,E801) -> 0.85 | H801: =IFERROR(G801/F801,"") -> 0.22849462 | I801: EQLFV-HDL8Z-N4QLR | J801: Closed | K801: =IFERROR(DATEDIF(C801,D801,"D"), "") -> 2 | L801: =IF(D801="","",TEXT(D801,"DDD")) -> Mon | M801: =IFERROR(VLOOKUP(A801, Entries!A:B,2,false),"") -> M2H | N801: =IFERROR(VLOOKUP(A801, Entries!A:K,11,false),"") | O801: =IFERROR(VLOOKUP(A801, Entries!A:I,8,false),"") -> TRUE
A802: NieR: Automata Game of the YoRHa Edition | B802: GreenMan | C802: 44324 | D802: 44325 | E802: 17.29 | F802: 24.04 | G802: =MINUS(F802,E802) -> 6.75 | H802: =IFERROR(G802/F802,"") -> 0.28078203 | I802: RX70B-9EJ37-MM6YQ | J802: Closed | K802: =IFERROR(DATEDIF(C802,D802,"D"), "") -> 1 | L802: =IF(D802="","",TEXT(D802,"DDD")) -> Sun | M802: =IFERROR(VLOOKUP(A802, Entries!A:B,2,false),"") -> Square Enix | N802: =IFERROR(VLOOKUP(A802, Entries!A:K,11,false),"") | O802: =IFERROR(VLOOKUP(A802, Entries!A:I,8,false),"") -> TRUE
A803: NieR: Automata - 3C3C1D119440927 DLC | B803: GreenMan | C803: 44324 | D803: 44353 | E803: 3.54 | F803: 4.49 | G803: =MINUS(F803,E803) -> 0.95 | H803: =IFERROR(G803/F803,"") -> 0.21158129 | I803: JWE9D-VZJT9-D7D2A | J803: Closed | K803: =IFERROR(DATEDIF(C803,D803,"D"), "") -> 29 | L803: =IF(D803="","",TEXT(D803,"DDD")) -> Sun | M803: =IFERROR(VLOOKUP(A803, Entries!A:B,2,false),"") -> Square Enix | N803: =IFERROR(VLOOKUP(A803, Entries!A:K,11,false),"") | O803: =IFERROR(VLOOKUP(A803, Entries!A:I,8,false),"") -> FALSE
A804: Resident Evil 7: Biohazard EMEA | B804: Fanatical | C804: 44326 | D804: 44326 | E804: 7.38 | F804: 12.36 | G804: =MINUS(F804,E804) -> 4.98 | H804: =IFERROR(G804/F804,"") -> 0.40291262 | I804: BV8MB-45VMW-4K25J | J804: Closed | K804: =IFERROR(DATEDIF(C804,D804,"D"), "") -> 0 | L804: =IF(D804="","",TEXT(D804,"DDD")) -> Mon | M804: =IFERROR(VLOOKUP(A804, Entries!A:B,2,false),"") -> CAPCOM | N804: =IFERROR(VLOOKUP(A804, Entries!A:K,11,false),"") | O804: =IFERROR(VLOOKUP(A804, Entries!A:I,8,false),"") -> FALSE
A805: Resident Evil 7: Biohazard EMEA | B805: Fanatical | C805: 44326 | D805: 44327 | E805: 7.38 | F805: 12.31 | G805: =MINUS(F805,E805) -> 4.93 | H805: =IFERROR(G805/F805,"") -> 0.40048741 | I805: AVY89-YBVBQ-LHV5B | J805: Closed | K805: =IFERROR(DATEDIF(C805,D805,"D"), "") -> 1 | L805: =IF(D805="","",TEXT(D805,"DDD")) -> Tue | M805: =IFERROR(VLOOKUP(A805, Entries!A:B,2,false),"") -> CAPCOM | N805: =IFERROR(VLOOKUP(A805, Entries!A:K,11,false),"") | O805: =IFERROR(VLOOKUP(A805, Entries!A:I,8,false),"") -> FALSE
... A820: Overload | B820: G2A | C820: 44328 | D820: 44498 | E820: 0.15 | F820: 0.41 | G820: =MINUS(F820,E820) -> 0.26 | H820: =IFERROR(G820/F820,"") -> 0.63414634 | I820: AYXLY-IZWM6-WXKWM | J820: Closed | K820: =IFERROR(DATEDIF(C820,D820,"D"), "") -> 170 | L820: =IF(D820="","",TEXT(D820,"DDD")) -> Fri | M820: =IFERROR(VLOOKUP(A820, Entries!A:B,2,false),"") -> Revival Productions | N820: =IFERROR(VLOOKUP(A820, Entries!A:K,11,false),"") | O820: =IFERROR(VLOOKUP(A820, Entries!A:I,8,false),"") -> FALSE
A821: Overload | B821: G2A | C821: 44328 | D821: 44501 | E821: 0.15 | F821: 0 | G821: =MINUS(F821,E821) -> -0.15 | H821: =IFERROR(G821/F821,"") | I821: BKX66-VRWT8-72KC | J821: Rejected | K821: =IFERROR(DATEDIF(C821,D821,"D"), "") -> 173 | L821: =IF(D821="","",TEXT(D821,"DDDD")) -> Monday | M821: =IFERROR(VLOOKUP(A821, Unique!A:E,5,false),"")
A822: The Sherlock Holmes Collection | B822: Fanatical | C822: 44328 | D822: 44329 | E822: 7.18 | F822: 11.47 | G822: =MINUS(F822,E822) -> 4.29 | H822: =IFERROR(G822/F822,"") -> 0.37401918 | I822: VQJDV-W6MXR-4JYLH | J822: Closed | K822: =IFERROR(DATEDIF(C822,D822,"D"), "") -> 1 | L822: =IF(D822="","",TEXT(D822,"DDD")) -> Thu | M822: =IFERROR(VLOOKUP(A822, Entries!A:B,2,false),"") -> Frogwares | N822: =IFERROR(VLOOKUP(A822, Entries!A:K,11,false),"") | O822: =IFERROR(VLOOKUP(A822, Entries!A:I,8,false),"") -> FALSE
A823: Garfield Kart Furious Racing | B823: Fanatical | C823: 44329 | D823: 44362 | E823: 2.61 | F823: 3.78 | G823: =MINUS(F823,E823) -> 1.17 | H823: =IFERROR(G823/F823,"") -> 0.30952381 | I823: img | J823: Closed | K823: =IFERROR(DATEDIF(C823,D823,"D"), "") -> 33 | L823: =IF(D823="","",TEXT(D823,"DDD")) -> Tue | M823: =IFERROR(VLOOKUP(A823, Entries!A:B,2,false),"") -> Microids | N823: =IFERROR(VLOOKUP(A823, Entries!A:K,11,false),"") | O823: =IFERROR(VLOOKUP(A823, Entries!A:I,8,false),"") -> FALSE
A824: Remothered: Tormented Fathers | B824: Fanatical | C824: 44329 | D824: 44352 | E824: 4.91 | F824: 7.64 | G824: =MINUS(F824,E824) -> 2.73 | H824: =IFERROR(G824/F824,"") -> 0.35732984 | I824: 53ZNW-Q5B2R-65JVY | J824: Closed | K824: =IFERROR(DATEDIF(C824,D824,"D"), "") -> 23 | L824: =IF(D824="","",TEXT(D824,"DDD")) -> Sat | M824: =IFERROR(VLOOKUP(A824, Entries!A:B,2,false),"") -> Modus Games | N824: =IFERROR(VLOOKUP(A824, Entries!A:K,11,false),"") | O824: =IFERROR(VLOOKUP(A824, Entries!A:I,8,false),"") -> FALSE
A825: The Sherlock Holmes Collection | B825: Fanatical | C825: 44329 | E825: 7.21 | G825: =MINUS(F825,E825) -> -7.21 | H825: =IFERROR(G825/F825,"") | I825: DEFEE-RXNK8-97JKI | J825: Open | K825: =IFERROR(DATEDIF(C825,D825,"D"), "") | L825: =IF(D825="","",TEXT(D825,"DDD")) | M825: =IFERROR(VLOOKUP(A825, Entries!A:B,2,false),"") -> Frogwares | O825: =IFERROR(VLOOKUP(A825, Entries!A:I,8,false),"") -> FALSE
A826: Praetorians HD Remaster | B826: Fanatical | C826: 44329 | D826: 44359 | E826: 2.88 | F826: 4.64 | G826: =MINUS(F826,E826) -> 1.76 | H826: =IFERROR(G826/F826,"") -> 0.37931034 | I826: IIFWA-9NAY4-L0C6X | J826: Closed | K826: =IFERROR(DATEDIF(C826,D826,"D"), "") -> 30 | L826: =IF(D826="","",TEXT(D826,"DDD")) -> Sat | M826: =IFERROR(VLOOKUP(A826, Entries!A:B,2,false),"") -> Kalypso Media | N826: =IFERROR(VLOOKUP(A826, Entries!A:K,11,false),"") | O826: =IFERROR(VLOOKUP(A826, Entries!A:I,8,false),"") -> FALSE
A827: Cultist Simulator | B827: Fanatical | C827: 44329 | D827: 44368 | E827: 2.87 | F827: 3.39 | G827: =MINUS(F827,E827) -> 0.52 | H827: =IFERROR(G827/F827,"") -> 0.15339233 | I827: RBDN5-6BK72-6XN44 | J827: Closed | K827: =IFERROR(DATEDIF(C827,D827,"D"), "") -> 39 | L827: =IF(D827="","",TEXT(D827,"DDD")) -> Mon | M827: =IFERROR(VLOOKUP(A827, Entries!A:B,2,false),"") -> Weather Factory | N827: =IFERROR(VLOOKUP(A827, Entries!A:K,11,false),"") | O827: =IFERROR(VLOOKUP(A827, Entries!A:I,8,false),"") -> FALSE
A828: DiRT Rally 2.0 Game of the Year Edition | B828: Fanatical | C828: 44329 | D828: 44361 | E828: 2.88 | F828: 4.47 | G828: =MINUS(F828,E828) -> 1.59 | H828: =IFERROR(G828/F828,"") -> 0.3557047 | I828: Img2h | J828: Closed | K828: =IFERROR(DATEDIF(C828,D828,"D"), "") -> 32 | L828: =IF(D828="","",TEXT(D828,"DDD")) -> Mon | M828: =IFERROR(VLOOKUP(A828, Entries!A:B,2,false),"") -> Codemasters | N828: =IFERROR(VLOOKUP(A828, Entries!A:K,11,false),"") | O828: =IFERROR(VLOOKUP(A828, Entries!A:I,8,false),"") -> FALSE
A829: Warpips | B829: G2A | C829: 44330 | D829: 44331 | E829: 6.71 | F829: 8.29 | G829: =MINUS(F829,E829) -> 1.58 | H829: =IFERROR(G829/F829,"") -> 0.19059107 | I829: BXRBG-73QYY-FB0EN | J829: Closed | K829: =IFERROR(DATEDIF(C829,D829,"D"), "") -> 1 | L829: =IF(D829="","",TEXT(D829,"DDD")) -> Sat | M829: =IFERROR(VLOOKUP(A829, Entries!A:B,2,false),"") -> Daedalic Entertainment | N829: =IFERROR(VLOOKUP(A829, Entries!A:K,11,false),"") | O829: =IFERROR(VLOOKUP(A829, Entries!A:I,8,false),"") -> FALSE
A830: Warpips | B830: GreenMan | C830: 44331 | D830: 44337 | E830: 6.62 | F830: 7.25 | G830: =MINUS(F830,E830) -> 0.63 | H830: =IFERROR(G830/F830,"") -> 0.086896552 | I830: HV0JA-027EZ-KJL2T | J830: Closed | K830: =IFERROR(DATEDIF(C830,D830,"D"), "") -> 6 | L830: =IF(D830="","",TEXT(D830,"DDD")) -> Fri | M830: =IFERROR(VLOOKUP(A830, Entries!A:B,2,false),"") -> Daedalic Entertainment | N830: =IFERROR(VLOOKUP(A830, Entries!A:K,11,false),"") | O830: =IFERROR(VLOOKUP(A830, Entries!A:I,8,false),"") -> FALSE
A831: Warpips | B831: G2A | C831: 44331 | D831: 44347 | E831: 6.67 | F831: 7.99 | G831: =MINUS(F831,E831) -> 1.32 | H831: =IFERROR(G831/F831,"") -> 0.16520651 | I831: 36W7G-L7NFG-8BTB8 | J831: Closed | K831: =IFERROR(DATEDIF(C831,D831,"D"), "") -> 16 | L831: =IF(D831="","",TEXT(D831,"DDD")) -> Mon | M831: =IFERROR(VLOOKUP(A831, Entries!A:B,2,false),"") -> Daedalic Entertainment | N831: =IFERROR(VLOOKUP(A831, Entries!A:K,11,false),"") | O831: =IFERROR(VLOOKUP(A831, Entries!A:I,8,false),"") -> FALSE
A832: Warpips | B832: G2A | C832: 44331 | D832: 44368 | E832: 6.67 | F832: 8.13 | G832: =MINUS(F832,E832) -> 1.46 | H832: =IFERROR(G832/F832,"") -> 0.1795818 | I832: QBGRF-5HZ6C-YDZ8X | J832: Closed | K832: =IFERROR(DATEDIF(C832,D832,"D"), "") -> 37 | L832: =IF(D832="","",TEXT(D832,"DDD")) -> Mon | M832: =IFERROR(VLOOKUP(A832, Entries!A:B,2,false),"") -> Daedalic Entertainment | N832: =IFERROR(VLOOKUP(A832, Entries!A:K,11,false),"") | O832: =IFERROR(VLOOKUP(A832, Entries!A:I,8,false),"") -> FALSE
...

Sheet Summary
B1: April | D1: May | F1: June | H1: July | J1: August | L1: September | N1: October | P1: November | R1: December | T1: January | V1: February | X1: March | Z1: Final
B2: 43922 | C2: 43951 | D2: 43952 | E2: 43982 | F2: 43983 | G2: 44012 | H2: 44013 | I2: 44043 | J2: 44044 | K2: 44074 | L2: 44075 | M2: 44104 | N2: 44105 | O2: 44135 | P2: 44136 | Q2: 44165 | R2: 44166 | S2: 44196 | T2: 44197 | U2: 44227 | V2: 44228 | W2: 44255 | X2: 44256 | Y2: 44286
A3: Total Income | B3: =IFERROR(__xludf.DUMMYFUNCTION("SUM(FILTER(Inventory!F:F,Inventory!J:J=""Closed"",Inventory!D:D>=B2,Inventory!D:D<=C2))"),65.97) -> 65.97 | D3: =IFERROR(__xludf.DUMMYFUNCTION("SUM(FILTER(Inventory!F:F,Inventory!J:J=""Closed"",Inventory!D:D>=D2,Inventory!D:D<=E2))"),346.67) -> 346.67 | F3: =IFERROR(__xludf.DUMMYFUNCTION("SUM(FILTER(Inventory!F:F,Inventory!J:J=""Closed"",Inventory!D:D>=F2,Inventory!D:D<=G2))"),410.05999999999966) -> 410.06 | H3: =IFERROR(__xludf.DUMMYFUNCTION("SUM(FILTER(Inventory!F:F,Inventory!J:J=""Closed"",Inventory!D:D>=H2,Inventory!D:D<=I2))"),416.56999999999994) -> 416.57 | J3: =SUMIFS(Inventory!F:F, Inventory!D:D,">="&J2,Inventory!D:D,"<="&K2) -> 432.68 | L3: =IFERROR(__xludf.DUMMYFUNCTION("SUM(FILTER(Inventory!F:F,Inventory!J:J=""Closed"",Inventory!D:D>=L2,Inventory!D:D<=M2))"),281.75000000000006) -> 281.75 | N3: =IFERROR(__xludf.DUMMYFUNCTION("SUM(FILTER(Inventory!F:F,Inventory!J:J=""Closed"",Inventory!D:D>=N2,Inventory!D:D<=O2))"),417.96999999999997) -> 417.97 | P3: =IFERROR(__xludf.DUMMYFUNCTION("SUM(FILTER(Inventory!F:F,Inventory!J:J=""Closed"",Inventory!D:D>=P2,Inventory!D:D<=Q2))"),219.04) -> 219.04 | R3: =IFERROR(__xludf.DUMMYFUNCTION("SUM(FILTER(Inventory!F:F,Inventory!J:J=""Closed"",Inventory!D:D>=R2,Inventory!D:D<=S2))"),370.59) -> 370.59 | T3: =IFERROR(__xludf.DUMMYFUNCTION("SUM(FILTER(Inventory!F:F,Inventory!J:J=""Closed"",Inventory!D:D>=T2,Inventory!D:D<=U2))"),318.6200000000002) -> 318.62 | V3: =IFERROR(__xludf.DUMMYFUNCTION("SUM(FILTER(Inventory!F:F,Inventory!J:J=""Closed"",Inventory!D:D>=V2,Inventory!D:D<=W2))"),102.67) -> 102.67 | X3: =IFERROR(__xludf.DUMMYFUNCTION("SUM(FILTER(Inventory!F:F,Inventory!J:J=""Closed"",Inventory!D:D>=X2,Inventory!D:D<=Y2))"),233.06000000000003) -> 233.06
A4: Total Spent | B4: =IFERROR(__xludf.DUMMYFUNCTION("SUM(FILTER(Inventory!E:E,Inventory!J:J=""Closed"",Inventory!D:D>=B2,Inventory!D:D<=C2))"),54.33) -> 54.33 | D4: =IFERROR(__xludf.DUMMYFUNCTION("SUM(FILTER(Inventory!E:E,Inventory!J:J=""Closed"",Inventory!D:D>=D2,Inventory!D:D<=E2))"),249.37000000000006) -> 249.37 | F4: =IFERROR(__xludf.DUMMYFUNCTION("SUM(FILTER(Inventory!E:E,Inventory!J:J=""Closed"",Inventory!D:D>=F2,Inventory!D:D<=G2))"),288.35999999999996) -> 288.36 | H4: =IFERROR(__xludf.DUMMYFUNCTION("SUM(FILTER(Inventory!E:E,Inventory!J:J=""Closed"",Inventory!D:D>=H2,Inventory!D:D<=I2))"),288.36999999999995) -> 288.37 | J4: =SUMIFS(Inventory!E:E, Inventory!D:D,">="&J2,Inventory!D:D,"<="&K2) -> 291.44 | L4: =IFERROR(__xludf.DUMMYFUNCTION("SUM(FILTER(Inventory!E:E,Inventory!J:J=""Closed"",Inventory!D:D>=L2,Inventory!D:D<=M2))"),195.22999999999988) -> 195.23 | N4: =IFERROR(__xludf.DUMMYFUNCTION("SUM(FILTER(Inventory!E:E,Inventory!J:J=""Closed"",Inventory!D:D>=N2,Inventory!D:D<=O2))"),290.0999999999999) -> 290.1 | P4: =IFERROR(__xludf.DUMMYFUNCTION("SUM(FILTER(Inventory!E:E,Inventory!J:J=""Closed"",Inventory!D:D>=P2,Inventory!D:D<=Q2))"),152.52999999999997) -> 152.53 | R4: =IFERROR(__xludf.DUMMYFUNCTION("SUM(FILTER(Inventory!E:E,Inventory!J:J=""Closed"",Inventory!D:D>=R2,Inventory!D:D<=S2))"),261.33) -> 261.33 | T4: =IFERROR(__xludf.DUMMYFUNCTION("SUM(FILTER(Inventory!E:E,Inventory!J:J=""Closed"",Inventory!D:D>=T2,Inventory!D:D<=U2))"),236.65999999999994) -> 236.66 | V4: =IFERROR(__xludf.DUMMYFUNCTION("SUM(FILTER(Inventory!E:E,Inventory!J:J=""Closed"",Inventory!D:D>=V2,Inventory!D:D<=W2))"),78.96000000000001) -> 78.96 | X4: =IFERROR(__xludf.DUMMYFUNCTION("SUM(FILTER(Inventory!E:E,Inventory!J:J=""Closed"",Inventory!D:D>=X2,Inventory!D:D<=Y2))"),176.26000000000002) -> 176.26
A5: Total Profit | B5: =IFERROR(__xludf.DUMMYFUNCTION("SUM(FILTER(Inventory!G:G,Inventory!J:J=""Closed"",Inventory!D:D>=B2,Inventory!D:D<=C2))"),11.639999999999997) -> 11.64 | D5: =IFERROR(__xludf.DUMMYFUNCTION("SUM(FILTER(Inventory!G:G,Inventory!J:J=""Closed"",Inventory!D:D>=D2,Inventory!D:D<=E2))"),97.29999999999998) -> 97.3 | F5: =IFERROR(__xludf.DUMMYFUNCTION("SUM(FILTER(Inventory!G:G,Inventory!J:J=""Closed"",Inventory!D:D>=F2,Inventory!D:D<=G2))"),121.69999999999999) -> 121.7 | H5: =IFERROR(__xludf.DUMMYFUNCTION("SUM(FILTER(Inventory!G:G,Inventory!J:J=""Closed"",Inventory!D:D>=H2,Inventory!D:D<=I2))"),128.20000000000002) -> 128.2 | J5: =SUMIFS(Inventory!G:G, Inventory!D:D,">="&J2,Inventory!D:D,"<="&K2) -> 141.24 | L5: =IFERROR(__xludf.DUMMYFUNCTION("SUM(FILTER(Inventory!G:G,Inventory!J:J=""Closed"",Inventory!D:D>=L2,Inventory!D:D<=M2))"),86.52000000000002) -> 86.52 | N5: =IFERROR(__xludf.DUMMYFUNCTION("SUM(FILTER(Inventory!G:G,Inventory!J:J=""Closed"",Inventory!D:D>=N2,Inventory!D:D<=O2))"),127.86999999999996) -> 127.87 | P5: =IFERROR(__xludf.DUMMYFUNCTION("SUM(FILTER(Inventory!G:G,Inventory!J:J=""Closed"",Inventory!D:D>=P2,Inventory!D:D<=Q2))"),66.50999999999999) -> 66.51 | R5: =IFERROR(__xludf.DUMMYFUNCTION("SUM(FILTER(Inventory!G:G,Inventory!J:J=""Closed"",Inventory!D:D>=R2,Inventory!D:D<=S2))"),109.25999999999999) -> 109.26 | T5: =IFERROR(__xludf.DUMMYFUNCTION("SUM(FILTER(Inventory!G:G,Inventory!J:J=""Closed"",Inventory!D:D>=T2,Inventory!D:D<=U2))"),81.96) -> 81.96 | V5: =IFERROR(__xludf.DUMMYFUNCTION("SUM(FILTER(Inventory!G:G,Inventory!J:J=""Closed"",Inventory!D:D>=V2,Inventory!D:D<=W2))"),23.709999999999994) -> 23.71 | X5: =IFERROR(__xludf.DUMMYFUNCTION("SUM(FILTER(Inventory!G:G,Inventory!J:J=""Closed"",Inventory!D:D>=X2,Inventory!D:D<=Y2))"),56.800000000000004) -> 56.8
A6: Sold Items | B6: =COUNTIFS(Inventory!J:J,"Closed", Inventory!D:D,">="&B2,Inventory!D:D,"<="&C2) -> 4 | D6: =COUNTIFS(Inventory!J:J,"Closed", Inventory!D:D,">="&D2,Inventory!D:D,"<="&E2) -> 38 | F6: =COUNTIFS(Inventory!J:J,"Closed", Inventory!D:D,">="&F2,Inventory!D:D,"<="&G2) -> 67 | H6: =COUNTIFS(Inventory!J:J,"Closed", Inventory!D:D,">="&H2,Inventory!D:D,"<="&I2) -> 69 | J6: =COUNTIFS(Inventory!J:J,"Closed", Inventory!D:D,">="&J2,Inventory!D:D,"<="&K2) -> 94 | L6: =COUNTIFS(Inventory!J:J,"Closed", Inventory!D:D,">="&L2,Inventory!D:D,"<="&M2) -> 70 | N6: =COUNTIFS(Inventory!J:J,"Closed", Inventory!D:D,">="&N2,Inventory!D:D,"<="&O2) -> 73 | P6: =COUNTIFS(Inventory!J:J,"Closed", Inventory!D:D,">="&P2,Inventory!D:D,"<="&Q2) -> 38 | R6: =COUNTIFS(Inventory!J:J,"Closed", Inventory!D:D,">="&R2,Inventory!D:D,"<="&S2) -> 80 | T6: =COUNTIFS(Inventory!J:J,"Closed", Inventory!D:D,">="&T2,Inventory!D:D,"<="&U2) -> 46 | V6: =COUNTIFS(Inventory!J:J,"Closed", Inventory!D:D,">="&V2,Inventory!D:D,"<="&W2) -> 16 | X6: =COUNTIFS(Inventory!J:J,"Closed", Inventory!D:D,">="&X2,Inventory!D:D,"<="&Y2) -> 29
A7: Avg Sold Price | B7: =IFERROR(__xludf.DUMMYFUNCTION("AVERAGE(FILTER(Inventory!F:F,Inventory!J:J=""Closed"",Inventory!D:D>=B2,Inventory!D:D<=C2))"),16.4925) -> 16.4925 | D7: =IFERROR(__xludf.DUMMYFUNCTION("AVERAGE(FILTER(Inventory!F:F,Inventory!J:J=""Closed"",Inventory!D:D>=D2,Inventory!D:D<=F2))"),8.972750000000001) -> 8.97275 | F7: =IFERROR(__xludf.DUMMYFUNCTION("AVERAGE(FILTER(Inventory!F:F,Inventory!J:J=""Closed"",Inventory!D:D>=F2,Inventory!D:D<=G2))"),6.120298507462682) -> 6.1202985 | H7: =IFERROR(__xludf.DUMMYFUNCTION("AVERAGE(FILTER(Inventory!F:F,Inventory!J:J=""Closed"",Inventory!D:D>=H2,Inventory!D:D<=I2))"),6.037246376811593) -> 6.0372464 | J7: =IFERROR(__xludf.DUMMYFUNCTION("AVERAGE(FILTER(Inventory!F:F,Inventory!J:J=""Closed"",Inventory!D:D>=J2,Inventory!D:D<=K2))"),4.602978723404255) -> 4.6029787 | L7: =IFERROR(__xludf.DUMMYFUNCTION("AVERAGE(FILTER(Inventory!F:F,Inventory!J:J=""Closed"",Inventory!D:D>=L2,Inventory!D:D<=M2))"),4.025000000000001) -> 4.025 | N7: =IFERROR(__xludf.DUMMYFUNCTION("AVERAGE(FILTER(Inventory!F:F,Inventory!J:J=""Closed"",Inventory!D:D>=N2,Inventory!D:D<=O2))"),5.725616438356164) -> 5.7256164 | P7: =IFERROR(__xludf.DUMMYFUNCTION("AVERAGE(FILTER(Inventory!F:F,Inventory!J:J=""Closed"",Inventory!D:D>=P2,Inventory!D:D<=Q2))"),5.7642105263157895) -> 5.7642105 | R7: =IFERROR(__xludf.DUMMYFUNCTION("AVERAGE(FILTER(Inventory!F:F,Inventory!J:J=""Closed"",Inventory!D:D>=R2,Inventory!D:D<=S2))"),4.632375) -> 4.632375 | T7: =IFERROR(__xludf.DUMMYFUNCTION("AVERAGE(FILTER(Inventory!F:F,Inventory!J:J=""Closed"",Inventory!D:D>=T2,Inventory!D:D<=U2))"),6.926521739130439) -> 6.9265217 | V7: =IFERROR(__xludf.DUMMYFUNCTION("AVERAGE(FILTER(Inventory!F:F,Inventory!J:J=""Closed"",Inventory!D:D>=V2,Inventory!D:D<=W2))"),6.416875) -> 6.416875 | X7: =IFERROR(__xludf.DUMMYFUNCTION("AVERAGE(FILTER(Inventory!F:F,Inventory!J:J=""Closed"",Inventory!D:D>=X2,Inventory!D:D<=Y2))"),8.036551724137933) -> 8.0365517
A8: Average Profit | B8: =IFERROR(__xludf.DUMMYFUNCTION("AVERAGE(FILTER(Inventory!G:G,Inventory!J:J=""Closed"",Inventory!D:D>=B2,Inventory!D:D<=C2))"),2.9099999999999993) -> 2.91 | D8: =IFERROR(__xludf.DUMMYFUNCTION("AVERAGE(FILTER(Inventory!G:G,Inventory!J:J=""Closed"",Inventory!D:D>=D2,Inventory!D:D<=E2))"),2.560526315789473) -> 2.5605263 | F8: =IFERROR(__xludf.DUMMYFUNCTION("AVERAGE(FILTER(Inventory!G:G,Inventory!J:J=""Closed"",Inventory!D:D>=F2,Inventory!D:D<=G2))"),1.8164179104477611) -> 1.8164179 | H8: =IFERROR(__xludf.DUMMYFUNCTION("AVERAGE(FILTER(Inventory!G:G,Inventory!J:J=""Closed"",Inventory!D:D>=H2,Inventory!D:D<=I2))"),1.857971014492754) -> 1.857971 | J8: =(J5/J6) -> 1.5025532 | L8: =IFERROR(__xludf.DUMMYFUNCTION("AVERAGE(FILTER(Inventory!G:G,Inventory!J:J=""Closed"",Inventory!D:D>=L2,Inventory!D:D<=M2))"),1.2360000000000004) -> 1.236 | N8: =IFERROR(__xludf.DUMMYFUNCTION("AVERAGE(FILTER(Inventory!G:G,Inventory!J:J=""Closed"",Inventory!D:D>=N2,Inventory!D:D<=O2))"),1.7516438356164379) -> 1.7516438 | P8: =IFERROR(__xludf.DUMMYFUNCTION("AVERAGE(FILTER(Inventory!G:G,Inventory!J:J=""Closed"",Inventory!D:D>=P2,Inventory!D:D<=Q2))"),1.7502631578947365) -> 1.7502632 | R8: =IFERROR(__xludf.DUMMYFUNCTION("AVERAGE(FILTER(Inventory!G:G,Inventory!J:J=""Closed"",Inventory!D:D>=R2,Inventory!D:D<=S2))"),1.3657499999999998) -> 1.36575 | T8: =IFERROR(__xludf.DUMMYFUNCTION("AVERAGE(FILTER(Inventory!G:G,Inventory!J:J=""Closed"",Inventory!D:D>=T2,Inventory!D:D<=U2))"),1.7817391304347825) -> 1.7817391 | V8: =IFERROR(__xludf.DUMMYFUNCTION("AVERAGE(FILTER(Inventory!G:G,Inventory!J:J=""Closed"",Inventory!D:D>=V2,Inventory!D:D<=W2))"),1.4818749999999996) -> 1.481875 | X8: =IFERROR(__xludf.DUMMYFUNCTION("AVERAGE(FILTER(Inventory!G:G,Inventory!J:J=""Closed"",Inventory!D:D>=X2,Inventory!D:D<=Y2))"),1.9586206896551726) -> 1.9586207
